[2023-10-04T11:00:49.332+0000] {taskinstance.py:1157} INFO - Dependencies all met for dep_context=non-requeueable deps ti=<TaskInstance: etl_dag.load_data manual__2023-10-04T11:00:34.988638+00:00 [queued]>
[2023-10-04T11:00:49.348+0000] {taskinstance.py:1157} INFO - Dependencies all met for dep_context=requeueable deps ti=<TaskInstance: etl_dag.load_data manual__2023-10-04T11:00:34.988638+00:00 [queued]>
[2023-10-04T11:00:49.349+0000] {taskinstance.py:1359} INFO - Starting attempt 1 of 1
[2023-10-04T11:00:49.378+0000] {taskinstance.py:1380} INFO - Executing <Task(PythonOperator): load_data> on 2023-10-04 11:00:34.988638+00:00
[2023-10-04T11:00:49.394+0000] {standard_task_runner.py:57} INFO - Started process 327 to run task
[2023-10-04T11:00:49.410+0000] {standard_task_runner.py:84} INFO - Running: ['airflow', 'tasks', 'run', 'etl_dag', 'load_data', 'manual__2023-10-04T11:00:34.988638+00:00', '--job-id', '2', '--raw', '--subdir', 'DAGS_FOLDER/etl_dag.py', '--cfg-path', '/tmp/tmpr357foj0']
[2023-10-04T11:00:49.415+0000] {standard_task_runner.py:85} INFO - Job 2: Subtask load_data
[2023-10-04T11:00:49.461+0000] {logging_mixin.py:151} WARNING - /home/airflow/.local/lib/python3.8/site-packages/airflow/settings.py:195 DeprecationWarning: The sql_alchemy_conn option in [core] has been moved to the sql_alchemy_conn option in [database] - the old setting has been used, but please update your config.
[2023-10-04T11:00:49.557+0000] {task_command.py:415} INFO - Running <TaskInstance: etl_dag.load_data manual__2023-10-04T11:00:34.988638+00:00 [running]> on host 9a46a127aae5
[2023-10-04T11:00:49.749+0000] {taskinstance.py:1660} INFO - Exporting env vars: AIRFLOW_CTX_DAG_OWNER='airflow' AIRFLOW_CTX_DAG_ID='etl_dag' AIRFLOW_CTX_TASK_ID='load_data' AIRFLOW_CTX_EXECUTION_DATE='2023-10-04T11:00:34.988638+00:00' AIRFLOW_CTX_TRY_NUMBER='1' AIRFLOW_CTX_DAG_RUN_ID='manual__2023-10-04T11:00:34.988638+00:00'
[2023-10-04T11:00:49.755+0000] {taskinstance.py:1935} ERROR - Task failed with exception
Traceback (most recent call last):
  File "/home/airflow/.local/lib/python3.8/site-packages/airflow/operators/python.py", line 192, in execute
    return_value = self.execute_callable()
  File "/home/airflow/.local/lib/python3.8/site-packages/airflow/operators/python.py", line 209, in execute_callable
    return self.python_callable(*self.op_args, **self.op_kwargs)
  File "/opt/airflow/plugins/etl.py", line 54, in load_data_from_json
    with open(file_path, 'r') as file:
FileNotFoundError: [Errno 2] No such file or directory: '/etl/resources/data.json'
[2023-10-04T11:00:49.789+0000] {taskinstance.py:1398} INFO - Marking task as FAILED. dag_id=etl_dag, task_id=load_data, execution_date=20231004T110034, start_date=20231004T110049, end_date=20231004T110049
[2023-10-04T11:00:49.817+0000] {standard_task_runner.py:104} ERROR - Failed to execute job 2 for task load_data ([Errno 2] No such file or directory: '/etl/resources/data.json'; 327)
[2023-10-04T11:00:49.858+0000] {local_task_job_runner.py:228} INFO - Task exited with return code 1
[2023-10-04T11:00:49.964+0000] {taskinstance.py:2776} INFO - 0 downstream tasks scheduled from follow-on schedule check
